Workbook

Sheet ФО - програми-дейности
B1: ОБЛАСТИ НА ПОЛИТИКИ/ФУНКЦИОНАЛНИ ОБЛАСТИ | C1: Консолидирани разходи | F1: Ведомствени разходи | I1: Администрирани разходи
A2: Код* | B2: И БЮДЖЕТНИ ПРОГРАМИ
B4: 2026 г.( в BGN) | C4: Общо разходи | D4: По бюджета на ПРБ | E4: По други бюджети и сметки за средства от ЕС | F4: Общо ведомствени | G4: По бюджета на ПРБ | H4: По други бюджети и сметки за средства от ЕС | I4: Общо администрирани | J4: По бюджета на ПРБ | K4: По други бюджети и сметки за средства от ЕС
B5: Общо разходи | C5: =C6+C16+C31+C37+C39 | D5: =D6+D16+D31+D37+D39 | F5: =F6+F16+F31+F37+F39 | G5: =G6+G16+G31+G37+G39
A6: ФО 01 | B6: Функционална област "Управление на съдебната власт" | C6: =C7+C12 | D6: =D7+D12 | F6: =F7+F12 | G6: =G7+G12
A7: П0101 | B7: Бюджетна програма "Организация и управление на съдебната власт" | C7: =C8+C9+C10+C11 | D7: =D8+D9+D10+D11 | F7: =F8+F9+F10+F11 | G7: =G8+G9+G10+G11
A8: 01.01.01. | B8: Дейност 1 Изборни членове на ВСС | C8: =F8 | D8: =G8 | F8: =G8 | G8: ='Програма 1'!C15
A9: 01.01.02. | B9: Дейност 2 Администрация на ВСС | C9: =F9 | D9: =G9 | F9: =G9 | G9: ='Програма 1'!C18
A10: 01.01.03. | B10: Дейност 3 Управление на недвижими имоти | C10: =F10 | D10: =G10 | F10: =G10 | G10: ='Програма 1'!C21
A11: 01.01.04. | B11: Дейност 4 Придобиване на ДМА | C11: =F11 | D11: =G11 | F11: =G11 | G11: ='Програма 1'!C23
A12: П0102 | B12: Бюджетна програма "Контрол върху дейността на органите на съдебната власт" | C12: =C13+C14+C15 | D12: =D13+D14+D15 | F12: =F13+F14+F15 | G12: =G13+G14+G15
A13: 01.02.01. | B13: Дейност 1 Главен инспектор и инспектори | C13: =F13 | D13: =G13 | F13: =G13 | G13: ='Програма 2'!C15
A14: 01.02.02. | B14: Дейност 2 Администрация на ИВСС | C14: =F14 | D14: =G14 | F14: =G14 | G14: ='Програма 2'!C18
A15: 01.02.03. | B15: Дейност 3 Капиталови разходи | C15: =F15 | D15: =G15 | F15: =G15 | G15: ='Програма 2'!C21
A16: ФО2 | B16: Функционална област "Правораздаване" | C16: =C17+C22+C27 | D16: =D17+D22+D27 | F16: =F17+F22+F27 | G16: =G17+G22+G27
A17: П0201 | B17: Бюджетна програма "Върховен съдебен надзор за точно и еднакво прилагане на законите от всички съдилища" | C17: =C18+C19+C20+C21 | D17: =D18+D19+D20+D21 | F17: =F18+F19+F20+F21 | G17: =G18+G19+G20+G21
A18: 02.01.01. | B18: Дейност 1 Магистрати във ВКС | C18: =F18 | D18: =G18 | F18: =G18 | G18: ='Програма 3'!C15
A19: 02.01.02. | B19: Дейност 2 Съдебни служители във ВКС | C19: =F19 | D19: =G19 | F19: =G19 | G19: ='Програма 3'!C18
A20: 02.01.03. | B20: Дейност 3 Капиталови разходи | C20: =F20 | D20: =G20 | F20: =G20 | G20: ='Програма 3'!C21
A21: 02.01.04. | B21: Дейност 4 Учебна и почивна дейност | C21: =F21 | D21: =G21 | F21: =G21 | G21: ='Програма 3'!C23
A22: П0202 | B22: Бюджетна програма "Върховен съдебен надзор за точно и еднакво прилагане на законите в административното правораздаване" | C22: =C23+C24+C25+C26 | D22: =D23+D24+D25+D26 | F22: =F23+F24+F25+F26 | G22: =G23+G24+G25+G26
A23: 02.02.01. | B23: Дейност 1 Магистрати във ВАС | C23: =F23 | D23: =G23 | F23: =G23 | G23: ='Програма 4'!C15
A24: 02.02.02. | B24: Дейност 2 Съдебни служители във ВАС | C24: =F24 | D24: =G24 | F24: =G24 | G24: ='Програма 4'!C18
A25: 02.02.03. | B25: Дейност 3 Капиталови разходи | C25: =F25 | D25: =G25 | F25: =G25 | G25: ='Програма 4'!C21
A26: 02.02.04. | B26: Дейност 4 Учебна и почивна дейност | C26: =F26 | D26: =G26 | F26: =G26 | G26: ='Програма 4'!C23
A27: П0203 | B27: Бюджетна програма "Правораздаване от районните, окръжните, военните, апелативните и административните съдилища" | C27: =C28+C29+C30 | D27: =D28+D29+D30 | F27: =F28+F29+F30 | G27: =G28+G29+G30
A28: 02.03.01. | B28: Дейност 1 Магистрати в съдилищата на РБ | C28: =F28 | D28: =G28 | F28: =G28 | G28: ='Програма 5'!C15
A29: 02.03.02. | B29: Дейност 2 Съдебни служителив съдилищата на РБ | C29: =F29 | D29: =G29 | F29: =G29 | G29: ='Програма 5'!C18
A30: 02.03.03. | B30: Дейност 3 Капиталови разходи | C30: =F30 | D30: =G30 | F30: =G30 | G30: ='Програма 5'!C21
A31: ФО3 | B31: Функционална област "Спазване на законността" | C31: =C32 | D31: =D32 | F31: =F32 | G31: =G32
A32: П0301 | B32: Бюджетна програма "Надзор за спазване на законността" | C32: =C33+C34+C35+C36 | D32: =D33+D34+D35+D36 | F32: =F33+F34+F35+F36 | G32: =G33+G34+G35+G36
A33: 03.01.01. | B33: Дейност 1 Магистрати в Прокуратура на БР | C33: =F33 | D33: =G33 | F33: =G33 | G33: ='Програма 6'!C15
A34: 03.01.02. | B34: Дейност 2 Съдебни служители в Прокуратура РБ | C34: =F34 | D34: =G34 | F34: =G34 | G34: ='Програма 6'!C18
A35: 03.01.03. | B35: Дейност 3 Капиталови разходи | C35: =F35 | D35: =G35 | F35: =G35 | G35: ='Програма 6'!C21
A36: 03.01.04. | B36: Дейност 4 Учебна и почивна дейност | C36: =F36 | D36: =G36 | F36: =G36 | G36: ='Програма 6'!C23
A37: ФО4 | B37: Функционална област "Електронно правосъдие" | C37: =C38 | D37: =D38 | F37: =F38 | G37: =G38
A38: П0401 | B38: Бюджетна програма "Утвърждаване и развитие на електронното правосъдие" | C38: =F38 | D38: =G38 | F38: =G38 | G38: ='Програма 7'!C10
A39: ФО5 | B39: Функционална област "Кадрови потенциал на съдебната власт" | C39: =C40 | D39: =D40 | F39: =F40 | G39: =G40
A40: П0501 | B40: Бюджетна програма "Обучение и квалификация на магистратите и съдебните служители" | C40: =D40 | D40: =G40 | F40: =G40 | G40: ='Програма 8'!C10
B43: ОБЛАСТИ НА ПОЛИТИКИ/ФУНКЦИОНАЛНИ ОБЛАСТИ | C43: Консолидирани разходи | F43: Ведомствени разходи | I43: Администрирани разходи
...

Sheet Програма 1
A1: Бюджетна прогноза по ведомствени разходни параграфи на програмата
A2: № | B2: 0600.01.01 Бюджетна програма "Организация и управление на съдебната власт" | C2: Прогноза/Проектобюджет | D2: Прогноза | E2: Прогноза | F2: Прогноза
C3: 2026 г.( в BGN) | D3: 2027 г.( в BGN) | E3: 2028 г.( в BGN) | F3: 2029 г.( в BGN)
B4: 1 | C4: 2 | D4: 3 | E4: 4 | F4: 5
A5: І. | B5: Общо ведомствени разходи: | C5: =C6+C7+C8 | D5: =D6+D7+D8 | E5: =E6+E7+E8 | F5: =F6+F7+F8
B6: Персонал | C6: =C11 | D6: =D11 | E6: =E11 | F6: =F11
B7: Издръжка | C7: =C12 | D7: =D12 | E7: =E12 | F7: =F12
B8: Капиталови разходи | C8: =C13 | D8: =D13 | E8: =E13 | F8: =F13
A10: 1 | B10: Ведомствени разходи по бюджета на Първостепенния разпоредител с бюджет: | C10: =C11+C12+C13 | D10: =D11+D12+D13 | E10: =E11+E12+E13 | F10: =F11+F12+F13
B11: Персонал | C11: =C16+C19 | D11: =D16+D19 | E11: =E16+E19 | F11: =F16+F19
B12: Издръжка | C12: =C17+C20 | D12: =D17+D20 | E12: =E17+E20 | F12: =F17+F20
B13: Капиталови разходи | C13: =C22+C24 | D13: =D22+D24 | E13: =E22+E24 | F13: =F22+F24
A15: 01.01.01. | B15: 01.01.01. Ведомствени разходи по Дейност 1 - Изборни членове на ВСС: | C15: =C16+C17 | D15: =D16+D17 | E15: =E16+E17 | F15: =F16+F17
A16: 01.01.01.P | B16: Персонал - включват се разходите по § 01, § 02 и § 05 за изборните членове на ВСС | C16: 0 | D16: 0 | E16: 0 | F16: 0
A17: 01.01.01.I | B17: Издръжка §10-00 - общият размер на разходите за издръжка изчислени пропорционално на заетата численост, с изключение на разходите предвидени в бюджетна програма "Утвърждаване и развитие на електронното правосъдие" | C17: 0 | D17: 0 | E17: 0 | F17: 0
A18: 01.01.02. | B18: 01.01.02. Ведомствени разходи по Дейност 2 - Администрация на ВСС: | C18: =C19+C20 | D18: =D19+D20 | E18: =E19+E20 | F18: =F19+F20
A19: 01.01.02.P | B19: Персонал - включват се разходите по § 01, § 02 и § 05 за администрацията на ВСС | C19: 0 | D19: 0 | E19: 0 | F19: 0
A20: 01.01.02.I | B20: Издръжка-§10-00 - общият размер на разходите за издръжка изчислени пропорционално на заетата численост, с изключение на разходите предвидени в бюджетна програма "Утвърждаване и развитие на електронното правосъдие" | C20: 0 | D20: 0 | E20: 0 | F20: 0
A21: 01.01.03. | B21: 01.01.03. Ведомствени разходи по Дейност 3 - Управление на недвижими имоти: | C21: =C22 | D21: =D22 | E21: =E22 | F21: =F22
A22: 01.01.03.K | B22: Капиталови разходи §51-00, §§ 52-02 и § 54-00- включват се разходи за основен ремонт, придобиване на сгради и придобиване на земя | C22: 0 | D22: 0 | E22: 0 | F22: 0
A23: 01.01.04. | B23: 01.01.04. Ведомствени разходи по Дейност 4 - Капиталови разходи: | C23: =C24 | D23: =D24 | E23: =E24 | F23: =F24
A24: 01.01.04.K | B24: Капиталови разходи §52-00 /без §§52-02, които са по Дейност 3/ - включва разходи за придобиване на ДМА с изключение на разходите предвидени в бюджетна програма "Утвърждаване и развитие на електронното правосъдие" | C24: 0 | D24: 0 | E24: 0 | F24: 0
A25: 2 | B25: Ведомствени разходи по други бюджети и сметки за средства от ЕС
B26: Персонал
B27: Издръжка
B28: Капиталови разходи
B29: От тях за: *
B30: 1.....................................
B31: 2....................................
A33: ІІ. | B33: Администрирани разходни параграфи по бюджета на ПРБ**
B34: 1. наименование на администриран разходен параграф (характер и/или нормативно основание за предоставянето/разходването на бюджетни средства) + вид разход (§ от ЕБК)
B35: 2....................................
A37: ІІІ. | B37: Администрирани разходни параграфи по други бюджети и сметки за средства от ЕС**
B38: 1. наименование на администриран разходен параграф (характер и/или нормативно основание за предоставянето/разходването на бюджетни средства) + вид разход (§ от ЕБК)
B39: 2....................................
B41: Общо администрирани разходи (ІІ.+ІІІ.):
B43: Общо разходи по бюджета (І.1+ІІ.): | C43: =C5 | D43: =D5 | E43: =E5 | F43: =F5
B45: Общо разходи (І.+ІІ.+ІІІ.): | C45: =C43 | D45: =D43 | E45: =E43 | F45: =F43
A47: 06.01.01. | B47: Численост на щатния персонал, в т.ч.: | C47: =C48+C49 | D47: =D48+D49 | E47: =E48+E49 | F47: =F48+F49
A48: 06.01.02. | B48: магистрати (вкл.съдия изпълнители и съдии по вписванията) | C48: 0 | D48: 0 | E48: 0 | F48: 0
...

Sheet Програма 2
A1: Бюджетна прогноза по ведомствени разходни параграфи на програмата
A2: № | B2: 0600.01.02 Бюджетна програма "Контрол върху дейността на органите на съдебната власт" | C2: Прогноза/Проектобюджет | D2: Прогноза | E2: Прогноза | F2: Прогноза
C3: 2026 г.( в BGN) | D3: 2027 г.( в BGN) | E3: 2028 г.( в BGN) | F3: 2029 г.( в BGN)
B4: 1 | C4: 2 | D4: 3 | E4: 4 | F4: 5
A5: І. | B5: Общо ведомствени разходи: | C5: =C6+C7+C8 | D5: =D6+D7+D8 | E5: =E6+E7+E8 | F5: =F6+F7+F8
B6: Персонал | C6: =C11 | D6: =D11 | E6: =E11 | F6: =F11
B7: Издръжка | C7: =C12 | D7: =D12 | E7: =E12 | F7: =F12
B8: Капиталови разходи | C8: =C13 | D8: =D13 | E8: =E13 | F8: =F13
A10: 1 | B10: Ведомствени разходи по бюджета на Първостепенния разпоредител с бюджет: | C10: =C11+C12+C13 | D10: =D11+D12+D13 | E10: =E11+E12+E13 | F10: =F11+F12+F13
B11: Персонал | C11: =C16+C19 | D11: =D16+D19 | E11: =E16+E19 | F11: =F16+F19
B12: Издръжка | C12: =C17+C20 | D12: =D17+D20 | E12: =E17+E20 | F12: =F17+F20
B13: Капиталови разходи | C13: =C22 | D13: =D22 | E13: =E22 | F13: =F22
A15: 01.02.01. | B15: 01.02.01. Ведомствени разходи по Дейност 1 - Главен инспектор и инспектори в ИВСС: | C15: =C16+C17 | D15: =D16+D17 | E15: =E16+E17 | F15: =F16+F17
A16: 01.02.01.P | B16: Персонал - включват се разходите по § 01, § 02 и § 05 за гл. инспектор и инспекторите на ИВСС | C16: 0 | D16: 0 | E16: 0 | F16: 0
A17: 01.02.01.I | B17: Издръжка § 10-00 - включва общият размер на разходите за издръжка изчислени пропорционално на заетата численост, с изключение на разходите предвидени в бюджетна програма "Утвърждаване и развитие на електронното правосъдие" | C17: 0 | D17: 0 | E17: 0 | F17: 0
A18: 01.02.02. | B18: 01.02.02. Ведомствени разходи по Дейност 2 - Администрация на ИВСС: | C18: =C19+C20 | D18: =D19+D20 | E18: =E19+E20 | F18: =F19+F20
A19: 01.02.02.P | B19: Персонал - включват се разходите по § 01, § 02 и § 05 за администрацията на ИВСС | C19: 0 | D19: 0 | E19: 0 | F19: 0
A20: 01.02.02.I | B20: Издръжка §10-00 - общият размер на разходите за издръжка изчислени пропорционално на заетата численост, с изключение на разходите предвидени в бюджетна програма "Утвърждаване и развитие на електронното правосъдие" | C20: 0 | D20: 0 | E20: 0 | F20: 0
A21: 01.02.03. | B21: 01.02.03. Ведомствени разходи по Дейност 3 - Капиталови разходи: | C21: =C22 | D21: =D22 | E21: =E22 | F21: =F22
A22: 01.02.03.K | B22: Капиталови разходи § 51-00 и §52-00 - включва разходи за основен ремонт и придобиване на ДМА с изключение на разходите предвидени в бюджетна програма "Утвърждаване и развитие на електронното правосъдие" | C22: 0 | D22: 0 | E22: 0 | F22: 0
A23: 2 | B23: Ведомствени разходи по други бюджети и сметки за средства от ЕС
B24: Персонал
B25: Издръжка
B26: Капиталови разходи
B27: От тях за: *
B28: 1.....................................
B29: 2....................................
A31: ІІ. | B31: Администрирани разходни параграфи по бюджета на ПРБ**
B32: 1. наименование на администриран разходен параграф (характер и/или нормативно основание за предоставянето/разходването на бюджетни средства) + вид разход (§ от ЕБК)
B33: 2....................................
A35: ІІІ. | B35: Администрирани разходни параграфи по други бюджети и сметки за средства от ЕС**
B36: 1. наименование на администриран разходен параграф (характер и/или нормативно основание за предоставянето/разходването на бюджетни средства) + вид разход (§ от ЕБК)
B37: 2....................................
B39: Общо администрирани разходи (ІІ.+ІІІ.):
B41: Общо разходи по бюджета (І.1+ІІ.): | C41: =C5 | D41: =D5 | E41: =E5 | F41: =F5
B43: Общо разходи (І.+ІІ.+ІІІ.): | C43: =C41 | D43: =D41 | E43: =E41 | F43: =F41
A45: 06.01.01. | B45: Численост на щатния персонал, в т.ч.: | C45: =C46+C47 | D45: =D46+D47 | E45: =E46+E47 | F45: =F46+F47
A46: 06.01.02. | B46: магистрати (вкл.съдия изпълнители и съдии по вписванията) | C46: 0 | D46: 0 | E46: 0 | F46: 0
A47: 06.01.03. | B47: съдебни служители | C47: 0 | D47: 0 | E47: 0 | F47: 0
A48: 06.02.01. | B48: Численост на заетите бройки, в т.ч.: | C48: =C49+C50 | D48: =D49+D50 | E48: =E49+E50 | F48: =F49+F50
...

Sheet Програма 3
A1: Бюджетна прогноза по ведомствени разходни параграфи на програмата
A2: № | B2: 0600.02.01. Бюджетна програма "Върховен съдебен надзор за точно и еднакво прилагане на законите от всички съдилища" | C2: Прогноза/Проектобюджет | D2: Прогноза | E2: Прогноза | F2: Прогноза
C3: 2026 г.( в BGN) | D3: 2027 г.( в BGN) | E3: 2028 г.( в BGN) | F3: 2029 г.( в BGN)
B4: 1 | C4: 2 | D4: 3 | E4: 4 | F4: 5
A5: І. | B5: Общо ведомствени разходи: | C5: =C6+C7+C8 | D5: =D6+D7+D8 | E5: =E6+E7+E8 | F5: =F6+F7+F8
B6: Персонал | C6: =C11 | D6: =D11 | E6: =E11 | F6: =F11
B7: Издръжка | C7: =C12 | D7: =D12 | E7: =E12 | F7: =F12
B8: Капиталови разходи | C8: =C13 | D8: =D13 | E8: =E13 | F8: =F13
A10: 1 | B10: Ведомствени разходи по бюджета на Първостепенния разпоредител с бюджет: | C10: =C11+C12+C13 | D10: =D11+D12+D13 | E10: =E11+E12+E13 | F10: =F11+F12+F13
B11: Персонал | C11: =C16+C19+C24 | D11: =D16+D19+D24 | E11: =E16+E19+E24 | F11: =F16+F19+F24
B12: Издръжка | C12: =C17+C20+C25 | D12: =D17+D20+D25 | E12: =E17+E20+E25 | F12: =F17+F20+F25
B13: Капиталови разходи | C13: =C22+C26 | D13: =D22+D26 | E13: =E22+E26 | F13: =F22+F26
A15: 02.01.01. | B15: Ведомствени разходи по Дейност 1 - Магистрати във ВКС: | C15: =C16+C17 | D15: =D16+D17 | E15: =E16+E17 | F15: =F16+F17
A16: 02.01.01.P | B16: Персонал - включват се разходите по § 01, § 02 и § 05 за магистрати във ВКС | C16: 0 | D16: 0 | E16: 0 | F16: 0
A17: 02.01.01.I | B17: Издръжка §10-00 - общият размер на разходите за издръжка изчислени пропорционално на заетата численост, с изключение на разходите предвидени в бюджетна програма "Утвърждаване и развитие на електронното правосъдие" и разходите за учебна и почивна дейност | C17: 0 | D17: 0 | E17: 0 | F17: 0
A18: 02.01.02. | B18: Ведомствени разходи по Дейност 2 - Съдебни служители във ВКС: | C18: =C19+C20 | D18: =D19+D20 | E18: =E19+E20 | F18: =F19+F20
A19: 02.01.02.P | B19: Персонал - включват се разходите по § 01, § 02 и § 05 за съдебни служители във ВКС с изключение на служителите от Раздел V "Учебни бази - специфични длъжности" от Класификатора на длъжностите в администрацията на съдилищата | C19: 0 | D19: 0 | E19: 0 | F19: 0
A20: 02.01.02.I | B20: Издръжка § 10-00 - общият размер на разходите за издръжка изчислени пропорционално на заетата численост, с изключение на разходите предвидени в бюджетна програма "Утвърждаване и развитие на електронното правосъдие" и разходите за учебна и почивна дейност | C20: 0 | D20: 0 | E20: 0 | F20: 0
A21: 02.01.03. | B21: Ведомствени разходи по Дейност 3 - Капиталови разходи: | C21: =C22 | D21: =D22 | E21: =E22 | F21: =F22
A22: 02.01.03.K | B22: Капиталови разходи §51-00 и §52-00- включва разходи за основен ремонт и придобиване на ДМА с изключение на разходите предвидени в бюджетна програма "Утвърждаване и развитие на електронното правосъдие" и капиталовите разходи за учебна и почивна дейност | C22: 0 | D22: 0 | E22: 0 | F22: 0
A23: 02.01.04. | B23: Ведомствени разходи по Дейност 4 - Учебна и почивна дейност: | C23: =C24+C25+C26 | D23: =D24+D25+D26 | E23: =E24+E25+E26 | F23: =F24+F25+F26
A24: 02.01.04.P | B24: Персонал - включват се разходите по § 01, § 02 и § 05 за всички служители от Раздел V "Учебни бази - специфични длъжности" от Класификатора на длъжностите в администрацията на съдилищата | C24: 0 | D24: 0 | E24: 0 | F24: 0
A25: 02.01.04.I | B25: Издръжка § 10-00 - общият размер на разходите за издръжка за учебна и почивна дейност | C25: 0 | D25: 0 | E25: 0 | F25: 0
A26: 02.01.04.K | B26: Капиталови разходи §51-00 и § 52-00- включва разходи за основен ремонт и придобиване на ДМА за учебна и почивна дейност | C26: 0 | D26: 0 | E26: 0 | F26: 0
A27: 2 | B27: Ведомствени разходи по други бюджети и сметки за средства от ЕС
B28: Персонал
B29: Издръжка
B30: Капиталови разходи
B31: От тях за: *
B32: 1.....................................
B33: 2....................................
A35: ІІ. | B35: Администрирани разходни параграфи по бюджета на ПРБ**
B36: 1. наименование на администриран разходен параграф (характер и/или нормативно основание за предоставянето/разходването на бюджетни средства) + вид разход (§ от ЕБК)
B37: 2....................................
A39: ІІІ. | B39: Администрирани разходни параграфи по други бюджети и сметки за средства от ЕС**
B40: 1. наименование на администриран разходен параграф (характер и/или нормативно основание за предоставянето/разходването на бюджетни средства) + вид разход (§ от ЕБК)
B41: 2....................................
B43: Общо администрирани разходи (ІІ.+ІІІ.):
B45: Общо разходи по бюджета (І.1+ІІ.): | C45: =C5 | D45: =D5 | E45: =E5 | F45: =F5
B47: Общо разходи (І.+ІІ.+ІІІ.): | C47: =C45 | D47: =D45 | E47: =E45 | F47: =F45
...

Sheet Програма 4
A1: Бюджетна прогноза по ведомствени разходни параграфи на програмата
A2: № | B2: 0600.02.02 Бюджетна програма "Върховен съдебен надзор за точно и еднакво прилагане на законите в административното правораздаване" | C2: Прогноза/Проектобюджет | D2: Прогноза | E2: Прогноза | F2: Прогноза
C3: 2026 г.( в BGN) | D3: 2027 г.( в BGN) | E3: 2028 г.( в BGN) | F3: 2029 г.( в BGN)
B4: 1 | C4: 2 | D4: 3 | E4: 4 | F4: 5
A5: І. | B5: Общо ведомствени разходи: | C5: =C6+C7+C8 | D5: =D6+D7+D8 | E5: =E6+E7+E8 | F5: =F6+F7+F8
B6: Персонал | C6: =C11 | D6: =D11 | E6: =E11 | F6: =F11
B7: Издръжка | C7: =C12 | D7: =D12 | E7: =E12 | F7: =F12
B8: Капиталови разходи | C8: =C13 | D8: =D13 | E8: =E13 | F8: =F13
A10: 1 | B10: Ведомствени разходи по бюджета на Първостепенния разпоредител с бюджет: | C10: =C11+C12+C13 | D10: =D11+D12+D13 | E10: =E11+E12+E13 | F10: =F11+F12+F13
B11: Персонал | C11: =C16+C19+C24 | D11: =D16+D19+D24 | E11: =E16+E19+E24 | F11: =F16+F19+F24
B12: Издръжка | C12: =C17+C20+C25 | D12: =D17+D20+D25 | E12: =E17+E20+E25 | F12: =F17+F20+F25
B13: Капиталови разходи | C13: =C22+C26 | D13: =D22+D26 | E13: =E22+E26 | F13: =F22+F26
A15: 02.02.01. | B15: Ведомствени разходи по Дейност 1 - Магистрати във ВАС: | C15: =C16+C17 | D15: =D16+D17 | E15: =E16+E17 | F15: =F16+F17
A16: 02.02.01.P | B16: Персонал - включват се разходите по § 01, § 02 и § 05 за магистрати във ВАС | C16: 0 | D16: 0 | E16: 0 | F16: 0
A17: 02.02.01.I | B17: Издръжка §10-00 - общият размер на разходите за издръжка изчислени пропорционално на заетата численост, с изключение на разходите предвидени в бюджетна програма "Утвърждаване и развитие на електронното правосъдие" и разходите за учебна и почивна дейност | C17: 0 | D17: 0 | E17: 0 | F17: 0
A18: 02.02.02. | B18: Ведомствени разходи по Дейност 2 - Съдебни служители във ВАС: | C18: =C19+C20 | D18: =D19+D20 | E18: =E19+E20 | F18: =F19+F20
A19: 02.02.02.P | B19: Персонал - включват се разходите по § 01, § 02 и § 05 за съдебни служители във ВАС с изключение на служителите от Раздел V "Учебни бази - специфични длъжности" от Класификатора на длъжностите в администрацията на съдилищата | C19: 0 | D19: 0 | E19: 0 | F19: 0
A20: 02.02.02.I | B20: Издръжка §10-00 - общият размер на разходите за издръжка изчислени пропорционално на заетата численост, с изключение на разходите предвидени в бюджетна програма "Утвърждаване и развитие на електронното правосъдие" и разходите за учебна и почивна дейност | C20: 0 | D20: 0 | E20: 0 | F20: 0
A21: 02.02.03. | B21: Ведомствени разходи по Дейност 3 - Капиталови разходи: | C21: =C22 | D21: =D22 | E21: =E22 | F21: =F22
A22: 02.02.03.K | B22: Капиталови разходи §51-00 и §52-00- включва разходи за основен ремонт и придобиване на ДМА с изключение на разходите предвидени в бюджетна програма "Утвърждаване и развитие на електронното правосъдие" и капиталовите разходи за учебна и почивна дейност | C22: 0 | D22: 0 | E22: 0 | F22: 0
A23: 02.02.04. | B23: Ведомствени разходи по Дейност 4 - Учебна и почивна дейност: | C23: =C24+C25+C26 | D23: =D24+D25+D26 | E23: =E24+E25+E26 | F23: =F24+F25+F26
A24: 02.02.04.P | B24: Персонал - включват се разходите по § 01, § 02 и § 05 за всички служители от Раздел V "Учебни бази - специфични длъжности" от Класификатора на длъжностите в администрацията на съдилищата | C24: 0 | D24: 0 | E24: 0 | F24: 0
A25: 02.02.04.I | B25: Издръжка § 10-00 - общият размер на разходите за издръжка само за учебна и почивна дейност | C25: 0 | D25: 0 | E25: 0 | F25: 0
A26: 02.02.04.K | B26: Капиталови разходи §51-00 и § 52-00 - включва разходи за основен ремонт и придобиване на ДМА само за учебна и почивна дейност | C26: 0 | D26: 0 | E26: 0 | F26: 0
A27: 2 | B27: Ведомствени разходи по други бюджети и сметки за средства от ЕС
B28: Персонал
B29: Издръжка
B30: Капиталови разходи
B31: От тях за: *
B32: 1.....................................
B33: 2....................................
A35: ІІ. | B35: Администрирани разходни параграфи по бюджета на ПРБ**
B36: 1. наименование на администриран разходен параграф (характер и/или нормативно основание за предоставянето/разходването на бюджетни средства) + вид разход (§ от ЕБК)
B37: 2....................................
A39: ІІІ. | B39: Администрирани разходни параграфи по други бюджети и сметки за средства от ЕС**
B40: 1. наименование на администриран разходен параграф (характер и/или нормативно основание за предоставянето/разходването на бюджетни средства) + вид разход (§ от ЕБК)
B41: 2....................................
B43: Общо администрирани разходи (ІІ.+ІІІ.):
B45: Общо разходи по бюджета (І.1+ІІ.): | C45: =C5 | D45: =D5 | E45: =E5 | F45: =F5
B47: Общо разходи (І.+ІІ.+ІІІ.): | C47: =C45 | D47: =D45 | E47: =E45 | F47: =F45
...

Sheet Програма 5
A1: Бюджетна прогноза по ведомствени разходни параграфи на програмата
A2: № | B2: 0600.02.03 Бюджетна програма "Правораздаване от районните, окръжните, военните, апелативните и административните съдилища" | C2: Прогноза/Проектобюджет | D2: Прогноза | E2: Прогноза | F2: Прогноза
C3: 2026 г.( в BGN) | D3: 2027 г.( в BGN) | E3: 2028 г.( в BGN) | F3: 2029 г.( в BGN)
B4: 1 | C4: 2 | D4: 3 | E4: 4 | F4: 5
A5: І. | B5: Общо ведомствени разходи: | C5: =C6+C7+C8 | D5: =D6+D7+D8 | E5: =E6+E7+E8 | F5: =F6+F7+F8
B6: Персонал | C6: =C11 | D6: =D11 | E6: =E11 | F6: =F11
B7: Издръжка | C7: =C12 | D7: =D12 | E7: =E12 | F7: =F12
B8: Капиталови разходи | C8: =C13 | D8: =D13 | E8: =E13 | F8: =F13
A10: 1 | B10: Ведомствени разходи по бюджета на Първостепенния разпоредител с бюджет: | C10: =C11+C12+C13 | D10: =D11+D12+D13 | E10: =E11+E12+E13 | F10: =F11+F12+F13
B11: Персонал | C11: =C16+C19 | D11: =D16+D19 | E11: =E16+E19 | F11: =F16+F19
B12: Издръжка | C12: =C17+C20 | D12: =D17+D20 | E12: =E17+E20 | F12: =F17+F20
B13: Капиталови разходи | C13: =C22
A15: 02.03.01. | B15: Ведомствени разходи по Дейност 1 - Магистрати в съдилищата на РБ: | C15: =C16+C17 | D15: =D16+D17 | E15: =E16+E17 | F15: =F16+F17
A16: 02.03.01.P | B16: Персонал - включват се разходите по § 01, § 02 и § 05 за магистрати | C16: 0 | D16: 0 | E16: 0 | F16: 0
A17: 02.03.01.I | B17: Издръжка §10-00- общият размер на разходите за издръжка изчислени пропорционално на заетата численост, с изключение на разходите предвидени в бюджетна програма "Утвърждаване и развитие на електронното правосъдие" | C17: 0 | D17: 0 | E17: 0 | F17: 0
A18: 02.03.02. | B18: Ведомствени разходи по Дейност 2 - Съдебни служители в съдилищата на РБ: | C18: =C19+C20 | D18: =D19+D20 | E18: =E19+E20 | F18: =F19+F20
A19: 02.03.02.P | B19: Персонал - включват се разходите по § 01, § 02 и § 05 за съдебни служители | C19: 0 | D19: 0 | E19: 0 | F19: 0
A20: 02.03.02.I | B20: Издръжка § 10-00- общият размер на разходите за издръжка изчислени пропорционално на заетата численост, с изключение на разходите предвидени в бюджетна програма "Утвърждаване и развитие на електронното правосъдие" | C20: 0 | D20: 0 | E20: 0 | F20: 0
A21: 02.03.03. | B21: Ведомствени разходи по Дейност 3 - Капиталови разходи: | C21: =C22 | D21: =D22 | E21: =E22 | F21: =F22
A22: 02.03.03.K | B22: Капиталови разходи § 51-00 и § 52-00- включва разходи за основен ремонт и придобиване на ДМА с изключение на разходите предвидени в бюджетна програма "Утвърждаване и развитие на електронното правосъдие" | C22: 0 | D22: 0 | E22: 0 | F22: 0
A23: 2 | B23: Ведомствени разходи по други бюджети и сметки за средства от ЕС
B24: Персонал
B25: Издръжка
B26: Капиталови разходи
B27: От тях за: *
B28: 1.....................................
B29: 2....................................
A31: ІІ. | B31: Администрирани разходни параграфи по бюджета на ПРБ**
B32: 1. наименование на администриран разходен параграф (характер и/или нормативно основание за предоставянето/разходването на бюджетни средства) + вид разход (§ от ЕБК)
B33: 2....................................
A35: ІІІ. | B35: Администрирани разходни параграфи по други бюджети и сметки за средства от ЕС**
B36: 1. наименование на администриран разходен параграф (характер и/или нормативно основание за предоставянето/разходването на бюджетни средства) + вид разход (§ от ЕБК)
B37: 2....................................
B39: Общо администрирани разходи (ІІ.+ІІІ.):
B41: Общо разходи по бюджета (І.1+ІІ.): | C41: =C5 | D41: =D5 | E41: =E5 | F41: =F5
B43: Общо разходи (І.+ІІ.+ІІІ.): | C43: =C41 | D43: =D41 | E43: =E41 | F43: =F41
A45: 06.01.01. | B45: Численост на щатния персонал, в т.ч.: | C45: =C46+C47 | D45: =D46+D47 | E45: =E46+E47 | F45: =F46+F47
A46: 06.01.02. | B46: магистрати (вкл.съдия изпълнители и съдии по вписванията) | C46: 0 | D46: 0 | E46: 0 | F46: 0
A47: 06.01.03. | B47: съдебни служители | C47: 0 | D47: 0 | E47: 0 | F47: 0
A48: 06.02.01. | B48: Численост на заетите бройки, в т.ч.: | C48: =C49+C50 | D48: =D49+D50 | E48: =E49+E50 | F48: =F49+F50
...

Sheet Програма 6
A1: Бюджетна прогноза по ведомствени разходни параграфи на програмата
A2: № | B2: 0600.03.01 Бюджетна програма "Надзор за спазване на законността" | C2: Прогноза/Проектобюджет | D2: Прогноза | E2: Прогноза | F2: Прогноза
C3: 2026 г.( в BGN) | D3: 2027 г.( в BGN) | E3: 2028 г.( в BGN) | F3: 2029 г.( в BGN)
B4: 1 | C4: 2 | D4: 3 | E4: 4 | F4: 5
A5: І. | B5: Общо ведомствени разходи: | C5: =C6+C7+C8 | D5: =D6+D7+D8 | E5: =E6+E7+E8 | F5: =F6+F7+F8
B6: Персонал | C6: =C11 | D6: =D11 | E6: =E11 | F6: =F11
B7: Издръжка | C7: =C12 | D7: =D12 | E7: =E12 | F7: =F12
B8: Капиталови разходи | C8: =C13 | D8: =D13 | E8: =E13 | F8: =F13
A10: 1 | B10: Ведомствени разходи по бюджета на Първостепенния разпоредител с бюджет: | C10: =C11+C12+C13 | D10: =D11+D12+D13 | E10: =E11+E12+E13 | F10: =F11+F12+F13
B11: Персонал | C11: =C16+C19+C24 | D11: =D16+D19+D24 | E11: =E16+E19+E24 | F11: =F16+F19+F24
B12: Издръжка | C12: =C17+C20+C25 | D12: =D17+D20+D25 | E12: =E17+E20+E25 | F12: =F17+F20+F25
B13: Капиталови разходи | C13: =C22+C26 | D13: =D22+D26 | E13: =E22+E26 | F13: =F22+F26
A15: 03.01.01. | B15: Ведомствени разходи по Дейност 1 - Магистрати в Прокуратура на РБ: | C15: =C16+C17 | D15: =D16+D17 | E15: =E16+E17 | F15: =F16+F17
A16: 03.01.01.P | B16: Персонал - включват се разходите по § 01, § 02 и § 05 за магистрати в Прокуратура на РБ | C16: 0 | D16: 0 | E16: 0 | F16: 0
A17: 03.01.01.I | B17: Издръжка § 10-00- общият размер на разходите за издръжка изчислени пропорционално на заетата численост, с изключение на разходите предвидени в бюджетна програма "Утвърждаване и развитие на електронното правосъдие" и разходите за учебна и почивна дейност | C17: 0 | D17: 0 | E17: 0 | F17: 0
A18: 03.01.02. | B18: Ведомствени разходи по Дейност 2 - Съдебни служители в Прокуратура на РБ: | C18: =C19+C20 | D18: =D19+D20 | E18: =E19+E20 | F18: =F19+F20
A19: 03.01.02.P | B19: Персонал - включват се разходите по § 01, § 02 и § 05 за съдебни служители в Прокуратура на РБ с изключение на служителите от Раздел С "Специфични длъжности" от Класификатора на длъжностите в администрацията на Прокуратура на РБ | C19: 0 | D19: 0 | E19: 0 | F19: 0
A20: 03.01.02.I | B20: Издръжка § 10-00 - общият размер на разходите за издръжка изчислени пропорционално на заетата численост, с изключение на разходите предвидени в бюджетна програма "Утвърждаване и развитие на електронното правосъдие" и разходите за учебна и почивна дейност | C20: 0 | D20: 0 | E20: 0 | F20: 0
A21: 03.01.03. | B21: Ведомствени разходи по Дейност 3 - Капиталови разходи: | C21: =C22 | D21: =D22 | E21: =E22 | F21: =F22
A22: 03.01.03.K | B22: Капиталови разходи §51-00 и § 52-00 - включва разходи за основен ремонт и придобиване на ДМА с изключение на разходите предвидени в бюджетна програма "Утвърждаване и развитие на електронното правосъдие" и капиталовите разходи за учебна и почивна дейност | C22: 0 | D22: 0 | E22: 0 | F22: 0
A23: 03.01.04. | B23: Ведомствени разходи по Дейност 4 - Учебна и почивна дейност: | C23: =C24+C25+C26 | D23: =D24+D25+D26 | E23: =E24+E25+E26 | F23: =F24+F25+F26
A24: 03.01.04.P | B24: Персонал - включват се разходите по § 01, § 02 и § 05 за всички служители от Раздел С "Специфични длъжности" от Класификатора на длъжностите в администрацията на Прокуратура на РБ | C24: 0 | D24: 0 | E24: 0 | F24: 0
A25: 03.01.04.I | B25: Издръжка §10-00 - общият размер на разходите за издръжка за учебна и почивна дейност | C25: 0 | D25: 0 | E25: 0 | F25: 0
A26: 03.01.04.K | B26: Капиталови разходи § 51-00 и § 52-00- включва разходи за основен ремонт и придобиване на ДМА за учебна и почивна дейност | C26: 0 | D26: 0 | E26: 0 | F26: 0
A27: 2 | B27: Ведомствени разходи по други бюджети и сметки за средства от ЕС
B28: Персонал
B29: Издръжка
B30: Капиталови разходи
B31: От тях за: *
B32: 1.....................................
B33: 2....................................
A35: ІІ. | B35: Администрирани разходни параграфи по бюджета на ПРБ**
B36: 1. наименование на администриран разходен параграф (характер и/или нормативно основание за предоставянето/разходването на бюджетни средства) + вид разход (§ от ЕБК)
B37: 2....................................
A39: ІІІ. | B39: Администрирани разходни параграфи по други бюджети и сметки за средства от ЕС**
B40: 1. наименование на администриран разходен параграф (характер и/или нормативно основание за предоставянето/разходването на бюджетни средства) + вид разход (§ от ЕБК)
B41: 2....................................
B43: Общо администрирани разходи (ІІ.+ІІІ.):
B45: Общо разходи по бюджета (І.1+ІІ.): | C45: =C5 | D45: =D5 | E45: =E5 | F45: =F5
B47: Общо разходи (І.+ІІ.+ІІІ.): | C47: =C45 | D47: =D45 | E47: =E45 | F47: =F45
...

Sheet Програма 7
A1: Бюджетна прогноза по ведомствени разходни параграфи на програмата
A2: № | B2: 0600.04.01 Бюджетна програма "Утвърждаване и развитие на електронното правосъдие" | C2: Прогноза/Проектобюджет | D2: Прогноза | E2: Прогноза | F2: Прогноза
C3: 2026 г.( в BGN) | D3: 2027 г.( в BGN) | E3: 2028 г.( в BGN) | F3: 2029 г.( в BGN)
B4: 1 | C4: 2 | D4: 3 | E4: 4 | F4: 5
A5: І. | B5: Общо ведомствени разходи: | C5: =C6+C7+C8 | D5: =D6+D7+D8 | E5: =E6+E7+E8 | F5: =F6+F7+F8
B6: Персонал
B7: Издръжка | C7: =C12 | D7: =D12 | E7: =E12 | F7: =F12
B8: Капиталови разходи | C8: =C13 | D8: =D13 | E8: =E13 | F8: =F13
A10: 04.01.01. | B10: Ведомствени разходи по бюджета на Първостепенния разпоредител с бюджет: | C10: =C12+C13 | D10: =D12+D13 | E10: =E12+E13 | F10: =F12+F13
A12: 04.01.01.I | B12: Издръжка - включва разходи по §§ 10-15 и §§ 10-20, които са в областта на електронното управление и използването на информационните и телекомуникационни технологии | C12: 0 | D12: 0 | E12: 0 | F12: 0
A13: 04.01.01.K | B13: Капиталови разходи - включва разходи по §§ 52-01, §§52-03 и §53-00, които са в областта на електронното управление и използването на информационните и телекомуникационни технологии | C13: 0 | D13: 0 | E13: 0 | F13: 0
A15: 2 | B15: Ведомствени разходи по други бюджети и сметки за средства от ЕС
B16: Персонал
B17: Издръжка
B18: Капиталови разходи
B19: От тях за: *
B20: 1.....................................
B21: 2....................................
A23: ІІ. | B23: Администрирани разходни параграфи по бюджета на ПРБ**
B24: 1. наименование на администриран разходен параграф (характер и/или нормативно основание за предоставянето/разходването на бюджетни средства) + вид разход (§ от ЕБК)
B25: 2....................................
A27: ІІІ. | B27: Администрирани разходни параграфи по други бюджети и сметки за средства от ЕС**
B28: 1. наименование на администриран разходен параграф (характер и/или нормативно основание за предоставянето/разходването на бюджетни средства) + вид разход (§ от ЕБК)
B29: 2....................................
B31: Общо администрирани разходи (ІІ.+ІІІ.):
B33: Общо разходи по бюджета (І.1+ІІ.): | C33: =C5 | D33: =D5 | E33: =E5 | F33: =F5
B35: Общо разходи (І.+ІІ.+ІІІ.): | C35: =C33 | D35: =D33 | E35: =E33 | F35: =F33

Sheet Програма 8
A1: Бюджетна прогноза по ведомствени разходни параграфи на програмата
A2: № | B2: 0600.05.01 Бюджетна програма "Обучение и квалификация на магистратите и съдебните служители" | C2: Прогноза/Проектобюджет | D2: Прогноза | E2: Прогноза | F2: Прогноза
C3: 2026 г.( в BGN) | D3: 2027 г.( в BGN) | E3: 2028 г.( в BGN) | F3: 2029 г.( в BGN)
B4: 1 | C4: 2 | D4: 3 | E4: 4 | F4: 5
A5: І. | B5: Общо ведомствени разходи: | C5: =C6+C7+C8 | D5: =D6+D7+D8 | E5: =E6+E7+E8 | F5: =F6+F7+F8
B6: Персонал | C6: =C11 | D6: =D11 | E6: =E11 | F6: =F11
B7: Издръжка | C7: =C12 | D7: =D12 | E7: =E12 | F7: =F12
B8: Капиталови разходи | C8: =C13 | D8: =D13 | E8: =E13 | F8: =F13
A10: 05.01.01. | B10: Ведомствени разходи по бюджета на Първостепенния разпоредител с бюджет: | C10: =C11+C12+C13 | D10: =D11+D12+D13 | E10: =E11+E12+E13 | F10: =F11+F12+F13
A11: 05.01.01.P | B11: Персонал - включват се разходите по § 01, § 02 и § 05 за директора на НИП и съдебните служители | C11: 0 | D11: 0 | E11: 0 | F11: 0
A12: 05.01.01.I | B12: Издръжка §10-00 - общият размер на разходите за издръжка, с изключение на разходите предвидени в бюджетна програма "Утвърждаване и развитие на електронното правосъдие" | C12: 0 | D12: 0 | E12: 0 | F12: 0
A13: 05.01.01.K | B13: Капиталови разходи § 51-00 и § 52-00 - включва разходи за основен ремонт и придобиване на ДМА с изключение на разходите предвидени в бюджетна програма "Утвърждаване и развитие на електронното правосъдие" | C13: 0 | D13: 0 | E13: 0 | F13: 0
A15: 2 | B15: Ведомствени разходи по други бюджети и сметки за средства от ЕС
B16: Персонал
B17: Издръжка
B18: Капиталови разходи
B19: От тях за: *
B20: 1.....................................
B21: 2....................................
A23: ІІ. | B23: Администрирани разходни параграфи по бюджета на ПРБ**
B24: 1. наименование на администриран разходен параграф (характер и/или нормативно основание за предоставянето/разходването на бюджетни средства) + вид разход (§ от ЕБК)
B25: 2....................................
A27: ІІІ. | B27: Администрирани разходни параграфи по други бюджети и сметки за средства от ЕС**
B28: 1. наименование на администриран разходен параграф (характер и/или нормативно основание за предоставянето/разходването на бюджетни средства) + вид разход (§ от ЕБК)
B29: 2....................................
B31: Общо администрирани разходи (ІІ.+ІІІ.):
B33: Общо разходи по бюджета (І.1+ІІ.): | C33: =C5 | D33: =D5 | E33: =E5 | F33: =F5
B35: Общо разходи (І.+ІІ.+ІІІ.): | C35: =C33 | D35: =D33 | E35: =E33 | F35: =F33
A37: 06.01.01. | B37: Численост на щатния персонал, в т.ч.: | C37: =C38 | D37: =D38 | E37: =E38 | F37: =F38
A38: 06.01.03. | B38: съдебни служители | C38: 0 | D38: 0 | E38: 0 | F38: 0
A39: 06.02.01. | B39: Численост на заетите бройки, в т.ч.: | C39: 0 | D39: 0 | E39: 0 | F39: 0
A40: 06.02.03. | B40: съдебни служители
